Workbook

Sheet Events
A1: DATA | B1: MESOS | C1: GRUP | D1: ESPAI | E1: TIPUS DE SERVEI | F1: LLOC DEL SERVEI | G1: NOM DEL SERVEI | H1: GESTIÓ LOGÍSTICA | I1: PREPARACIÓ | J1: PERSONAL DE RENTAT | K1: COMPLEMENT RESPONSABLE EVENT | L1: PERSONAL SERVEI LOGÍSTICS | M1: HORES SERVEI | N1: PERSONAL TRANSPORT LOGÍSTICS | O1: HORES | P1: TOTAL HORES | Q1: LLOGUER VEHICLES | R1: MANTENIMENT VEHICLES | S1: CAMIONS GRAN | T1: KM | U1: CAMIONS CUINA | V1: KM2 | W1: CAMIONS PETIT | X1: KM3 | Y1: TOTAL KM | Z1: TOTAL COST | AA1: FACTURACIO | AB1: % | AF1: PREU LOGÍSITIC
A2: 45295 | B2: 45292 | C2: CASAMENTS | D2: EXTERN | E2: CASAMENT | F2: MASIA ROSAS | G2: C - ANA i JOSEP M x 60 (JONA) | H2: =(VLOOKUP(B2,$AD$12:$AG$17,2,0)*AB2) -> 150.5316 | I2: =(VLOOKUP(B2,$AD$12:$AG$17,3,0)*AB2) -> 166.61611 | J2: =(VLOOKUP(B2,$AD$12:$AG$17,4,0)*AB2) -> 120.11763 | K2: 0 | L2: 4 | M2: 17.72 | N2: 4 | O2: 0 | P2: =(L2*M2)+(N2*O2) -> 70.88 | Q2: 0 | R2: 35.83 | S2: 0 | T2: 96 | U2: 1 | V2: 96 | W2: 4 | X2: 96 | Y2: =(S2*T2)+(W2*X2)+(U2*V2) -> 480 | Z2: =((P2*$AF$7)+(Y2*$AF$8/100)*$AG$7)+Events!$H2+Events!$I2+Events!$J2+Events!$R2+Events!$Q2+Tabla1[[#This Row],[COMPLEMENT RESPONSABLE EVENT]] -> 1875.9434 | AA2: 12342 | AB2: =AA2/SUM($AA$2:$AA$38) -> 0.027902213
A3: 45298 | B3: 45292 | C3: EVENTS | D3: EXTERN | E3: BANQUET | F3: GRÍFOLS | G3: E - Grifols dinar X 39 cristina | H3: =(VLOOKUP(B3,$AD$12:$AG$17,2,0)*AB3) -> 53.287359 | I3: =(VLOOKUP(B3,$AD$12:$AG$17,3,0)*AB3) -> 58.981186 | J3: =(VLOOKUP(B3,$AD$12:$AG$17,4,0)*AB3) -> 42.52098 | K3: 0 | L3: 1 | M3: 12.75 | N3: 0 | O3: 0 | P3: =(L3*M3)+(N3*O3) -> 12.75 | Q3: 0 | R3: 35.83 | S3: 0 | T3: 96 | U3: 1 | V3: 96 | W3: 1 | X3: 96 | Y3: =(S3*T3)+(W3*X3)+(U3*V3) -> 192 | Z3: =((P3*$AF$7)+(Y3*$AF$8/100)*$AG$7)+Events!$H3+Events!$I3+Events!$J3+Events!$R3+Events!$Q3+Tabla1[[#This Row],[COMPLEMENT RESPONSABLE EVENT]] -> 470.92273 | AA3: 4369 | AB3: =AA3/SUM($AA$2:$AA$38) -> 0.0098772298
A4: 45299 | B4: 45292 | C4: EVENTS | D4: EXTERN | E4: COFFEE | F4: AXA | G4: E-AMEX coffee 250-laia | H4: =(VLOOKUP(B4,$AD$12:$AG$17,2,0)*AB4) -> 55.351039 | I4: =(VLOOKUP(B4,$AD$12:$AG$17,3,0)*AB4) -> 61.265374 | J4: =(VLOOKUP(B4,$AD$12:$AG$17,4,0)*AB4) -> 44.167707 | K4: 0 | L4: 1 | M4: 13.8 | N4: 0 | O4: 0 | P4: =(L4*M4)+(N4*O4) -> 13.8 | Q4: 0 | R4: 35.83 | S4: 0 | T4: 112 | U4: 1 | V4: 112 | W4: 1 | X4: 112 | Y4: =(S4*T4)+(W4*X4)+(U4*V4) -> 224 | Z4: =((P4*$AF$7)+(Y4*$AF$8/100)*$AG$7)+Events!$H4+Events!$I4+Events!$J4+Events!$R4+Events!$Q4+Tabla1[[#This Row],[COMPLEMENT RESPONSABLE EVENT]] -> 504.28452 | AA4: 4538.2 | AB4: =AA4/SUM($AA$2:$AA$38) -> 0.010259749
A5: 45300 | B5: 45292 | C5: EVENTS | D5: EXTERN | E5: COFFEE | F5: AXA | G5: E-AMEX coffee 250&140-laia | H5: =(VLOOKUP(B5,$AD$12:$AG$17,2,0)*AB5) -> 56.104795 | I5: =(VLOOKUP(B5,$AD$12:$AG$17,3,0)*AB5) -> 62.09967 | J5: =(VLOOKUP(B5,$AD$12:$AG$17,4,0)*AB5) -> 44.769171 | K5: 0 | L5: 1 | M5: 12.3 | N5: 0 | O5: 0 | P5: =(L5*M5)+(N5*O5) -> 12.3 | Q5: 0 | R5: 35.83 | S5: 0 | T5: 112 | U5: 1 | V5: 112 | W5: 1 | X5: 112 | Y5: =(S5*T5)+(W5*X5)+(U5*V5) -> 224 | Z5: =((P5*$AF$7)+(Y5*$AF$8/100)*$AG$7)+Events!$H5+Events!$I5+Events!$J5+Events!$R5+Events!$Q5+Tabla1[[#This Row],[COMPLEMENT RESPONSABLE EVENT]] -> 479.47404 | AA5: 4600 | AB5: =AA5/SUM($AA$2:$AA$38) -> 0.010399464
A6: 45300 | B6: 45292 | C6: EVENTS | D6: EXTERN | E6: BANQUET | F6: CODORNIU | G6: E - Envy | H6: =(VLOOKUP(B6,$AD$12:$AG$17,2,0)*AB6) -> 103.6719 | I6: =(VLOOKUP(B6,$AD$12:$AG$17,3,0)*AB6) -> 114.74939 | J6: =(VLOOKUP(B6,$AD$12:$AG$17,4,0)*AB6) -> 82.725643 | K6: 0 | L6: 1 | M6: 10 | N6: 2 | O6: 3 | P6: =(L6*M6)+(N6*O6) -> 16 | Q6: 0 | R6: 35.83 | S6: 1 | T6: 20 | U6: 1 | V6: 20 | W6: 0 | X6: 20 | Y6: =(S6*T6)+(W6*X6)+(U6*V6) -> 40 | Z6: =((P6*$AF$7)+(Y6*$AF$8/100)*$AG$7)+Events!$H6+Events!$I6+Events!$J6+Events!$R6+Events!$Q6+Tabla1[[#This Row],[COMPLEMENT RESPONSABLE EVENT]] -> 635.56094 | AA6: 8500 | AB6: =AA6/SUM($AA$2:$AA$38) -> 0.0192164
A7: 45302 | B7: 45292 | C7: EVENTS | D7: EXTERN | E7: COCTEL | F7: TIK TOK CODORNIU | G7: E - ThevenueAgency 300 cristina | H7: =(VLOOKUP(B7,$AD$12:$AG$17,2,0)*AB7) -> 473.69522 | I7: =(VLOOKUP(B7,$AD$12:$AG$17,3,0)*AB7) -> 524.31021 | J7: =(VLOOKUP(B7,$AD$12:$AG$17,4,0)*AB7) -> 377.98806 | K7: 0 | L7: 3 | M7: 13 | N7: 3 | O7: 5 | P7: =(L7*M7)+(N7*O7) -> 54 | Q7: 0 | R7: 35.83 | S7: 2 | T7: 20 | U7: 8 | V7: 20 | W7: 6 | X7: 20 | Y7: =(S7*T7)+(W7*X7)+(U7*V7) -> 320 | Z7: =((P7*$AF$7)+(Y7*$AF$8/100)*$AG$7)+Events!$H7+Events!$I7+Events!$J7+Events!$R7+Events!$Q7+Tabla1[[#This Row],[COMPLEMENT RESPONSABLE EVENT]] -> 2468.4955 | AA7: 38838 | AB7: =AA7/SUM($AA$2:$AA$38) -> 0.087803125 | AD7: PREU HORA LOGISTIC | AF7: 18 | AG7: 1.47 | AH7: Preu litre
A8: 45302 | B8: 45292 | C8: EVENTS | D8: EXTERN | E8: BANQUET | F8: MUSEU MARÍTIM | G8: E- BCDME cena x 270 MM | H8: =(VLOOKUP(B8,$AD$12:$AG$17,2,0)*AB8) -> 269.76649 | I8: =(VLOOKUP(B8,$AD$12:$AG$17,3,0)*AB8) -> 298.59141 | J8: =(VLOOKUP(B8,$AD$12:$AG$17,4,0)*AB8) -> 215.26186 | K8: 0 | L8: 4 | M8: 13.5 | N8: 1 | O8: 4 | P8: =(L8*M8)+(N8*O8) -> 58 | Q8: 0 | R8: 35.83 | S8: 0 | T8: 120 | U8: 2 | V8: 120 | W8: 4 | X8: 120 | Y8: =(S8*T8)+(W8*X8)+(U8*V8) -> 720 | Z8: =((P8*$AF$7)+(Y8*$AF$8/100)*$AG$7)+Events!$H8+Events!$I8+Events!$J8+Events!$R8+Events!$Q8+Tabla1[[#This Row],[COMPLEMENT RESPONSABLE EVENT]] -> 2053.9618 | AA8: 22118 | AB8: =AA8/SUM($AA$2:$AA$38) -> 0.050003335 | AD8: Camió | AF8: 18 | AG8: L/KM
A9: 45304 | B9: 45292 | C9: EVENTS | D9: EXTERN | E9: COCTEL | F9: TORRE AGBAR | G9: E- Sibaris Catering coctelx108 MM | H9: =(VLOOKUP(B9,$AD$12:$AG$17,2,0)*AB9) -> 147.2263 | I9: =(VLOOKUP(B9,$AD$12:$AG$17,3,0)*AB9) -> 162.95763 | J9: =(VLOOKUP(B9,$AD$12:$AG$17,4,0)*AB9) -> 117.48015 | K9: 0 | L9: 2 | M9: 13 | N9: 0 | O9: 0 | P9: =(L9*M9)+(N9*O9) -> 26 | Q9: 0 | R9: 35.83 | S9: 0 | T9: 132 | U9: 1 | V9: 132 | W9: 1 | X9: 132 | Y9: =(S9*T9)+(W9*X9)+(U9*V9) -> 264 | Z9: =((P9*$AF$7)+(Y9*$AF$8/100)*$AG$7)+Events!$H9+Events!$I9+Events!$J9+Events!$R9+Events!$Q9+Tabla1[[#This Row],[COMPLEMENT RESPONSABLE EVENT]] -> 1001.3485 | AA9: 12071 | AB9: =AA9/SUM($AA$2:$AA$38) -> 0.027289549
A10: 45305 | B10: 45292 | C10: EVENTS | D10: EXTERN | E10: BRUNCH | F10: CASA CORBERA | G10: P - NATALIE x 50 afv | H10: =(VLOOKUP(B10,$AD$12:$AG$17,2,0)*AB10) -> 25.856992 | I10: =(VLOOKUP(B10,$AD$12:$AG$17,3,0)*AB10) -> 28.619848 | J10: =(VLOOKUP(B10,$AD$12:$AG$17,4,0)*AB10) -> 20.632749 | K10: 0 | L10: 1 | M10: 10.9 | N10: 0 | O10: 0 | P10: =(L10*M10)+(N10*O10) -> 10.9 | Q10: 0 | R10: 35.83 | S10: 0 | T10: 88 | U10: 1 | V10: 88 | W10: 1 | X10: 88 | Y10: =(S10*T10)+(W10*X10)+(U10*V10) -> 176 | Z10: =((P10*$AF$7)+(Y10*$AF$8/100)*$AG$7)+Events!$H10+Events!$I10+Events!$J10+Events!$R10+Events!$Q10+Tabla1[[#This Row],[COMPLEMENT RESPONSABLE EVENT]] -> 353.70919 | AA10: 2120 | AB10: =AA10/SUM($AA$2:$AA$38) -> 0.0047927963
A11: 45307 | B11: 45292 | C11: EVENTS | D11: EXTERN | E11: COCTEL | F11: POBLE ESPANYOL | G11: E-HB sopar CCTEL 300-laia | H11: =(VLOOKUP(B11,$AD$12:$AG$17,2,0)*AB11) -> 259.15537 | I11: =(VLOOKUP(B11,$AD$12:$AG$17,3,0)*AB11) -> 286.84647 | J11: =(VLOOKUP(B11,$AD$12:$AG$17,4,0)*AB11) -> 206.79464 | K11: 0 | L11: 2 | M11: 12 | N11: 0 | O11: 0 | P11: =(L11*M11)+(N11*O11) -> 24 | Q11: 0 | R11: 35.83 | S11: 0 | T11: 120 | U11: 2 | V11: 120 | W11: 2 | X11: 120 | Y11: =(S11*T11)+(W11*X11)+(U11*V11) -> 480 | Z11: =((P11*$AF$7)+(Y11*$AF$8/100)*$AG$7)+Events!$H11+Events!$I11+Events!$J11+Events!$R11+Events!$Q11+Tabla1[[#This Row],[COMPLEMENT RESPONSABLE EVENT]] -> 1347.6345 | AA11: 21248 | AB11: =AA11/SUM($AA$2:$AA$38) -> 0.04803648 | AE11: GESTIÓ | AF11: PREPARACIÓ | AG11: RENTAT
A12: 45310 | B12: 45292 | C12: EVENTS | D12: EXTERN | E12: COCTEL | F12: LA PALOMA | G12: E- LAPICA sopar cctel 270-laia | H12: =(VLOOKUP(B12,$AD$12:$AG$17,2,0)*AB12) -> 199.59891 | I12: =(VLOOKUP(B12,$AD$12:$AG$17,3,0)*AB12) -> 220.92633 | J12: =(VLOOKUP(B12,$AD$12:$AG$17,4,0)*AB12) -> 159.27119 | K12: 0 | L12: 2 | M12: 11.5 | N12: 4 | O12: 0 | P12: =(L12*M12)+(N12*O12) -> 23 | Q12: 0 | R12: 35.83 | S12: 0 | T12: 123 | U12: 1 | V12: 123 | W12: 2 | X12: 123 | Y12: =(S12*T12)+(W12*X12)+(U12*V12) -> 369 | Z12: =((P12*$AF$7)+(Y12*$AF$8/100)*$AG$7)+Events!$H12+Events!$I12+Events!$J12+Events!$R12+Events!$Q12+Tabla1[[#This Row],[COMPLEMENT RESPONSABLE EVENT]] -> 1127.2638 | AA12: 16365 | AB12: =AA12/SUM($AA$2:$AA$38) -> 0.036997223 | AD12: 45292 | AE12: 5394.97 | AF12: 5971.43 | AG12: 4304.95
A13: 45313 | B13: 45292 | C13: EVENTS | D13: EXTERN | E13: COCTEL | F13: EXÒTICA | G13: E-EXOTICA COCKTAIL LUNCH 75 PAX AFV | H13: =(VLOOKUP(B13,$AD$12:$AG$17,2,0)*AB13) -> 63.361828 | I13: =(VLOOKUP(B13,$AD$12:$AG$17,3,0)*AB13) -> 70.132127 | J13: =(VLOOKUP(B13,$AD$12:$AG$17,4,0)*AB13) -> 50.559966 | K13: 0 | L13: 1 | M13: 10.3 | N13: 0 | O13: 0 | P13: =(L13*M13)+(N13*O13) -> 10.3 | Q13: 0 | R13: 35.83 | S13: 0 | T13: 122 | U13: 1 | V13: 122 | W13: 1 | X13: 122 | Y13: =(S13*T13)+(W13*X13)+(U13*V13) -> 244 | Z13: =((P13*$AF$7)+(Y13*$AF$8/100)*$AG$7)+Events!$H13+Events!$I13+Events!$J13+Events!$R13+Events!$Q13+Tabla1[[#This Row],[COMPLEMENT RESPONSABLE EVENT]] -> 469.84632 | AA13: 5195 | AB13: =AA13/SUM($AA$2:$AA$38) -> 0.011744612 | AD13: 45323 | AE13: 5556.36 | AF13: 5801.08 | AG13: 4318.56
A14: 45313 | B14: 45292 | C14: EVENTS | D14: EXTERN | E14: BANQUET | F14: GRÍFOLS | G14: E - Grifols sopar 14 cristina | H14: =(VLOOKUP(B14,$AD$12:$AG$17,2,0)*AB14) -> 22.807819 | I14: =(VLOOKUP(B14,$AD$12:$AG$17,3,0)*AB14) -> 25.244866 | J14: =(VLOOKUP(B14,$AD$12:$AG$17,4,0)*AB14) -> 18.199641 | K14: 0 | L14: 0 | M14: 0 | N14: 0 | O14: 0 | P14: =(L14*M14)+(N14*O14) -> 0 | Q14: 0 | R14: 35.83 | S14: 0 | T14: 96 | U14: 1 | V14: 96 | W14: 0 | X14: 96 | Y14: =(S14*T14)+(W14*X14)+(U14*V14) -> 96 | Z14: =((P14*$AF$7)+(Y14*$AF$8/100)*$AG$7)+Events!$H14+Events!$I14+Events!$J14+Events!$R14+Events!$Q14+Tabla1[[#This Row],[COMPLEMENT RESPONSABLE EVENT]] -> 127.48393 | AA14: 1870 | AB14: =AA14/SUM($AA$2:$AA$38) -> 0.0042276081 | AD14: 45352 | AE14: 6293.52 | AF14: 6141.96 | AG14: 4593.06
A15: 45314 | B15: 45292 | C15: EVENTS | D15: MASIA PROPIES | E15: PAELLES | F15: MASIA ESPLUGUES | G15: E High Fidelity ccurs 55 MG | H15: =(VLOOKUP(B15,$AD$12:$AG$17,2,0)*AB15) -> 41.078467 | I15: =(VLOOKUP(B15,$AD$12:$AG$17,3,0)*AB15) -> 45.467758 | J15: =(VLOOKUP(B15,$AD$12:$AG$17,4,0)*AB15) -> 32.778819 | K15: 0 | L15: 0 | M15: 0 | N15: 1 | O15: 3 | P15: =(L15*M15)+(N15*O15) -> 3 | Q15: 0 | R15: 35.83 | S15: 0 | T15: 104 | U15: 1 | V15: 104 | W15: 1 | X15: 104 | Y15: =(S15*T15)+(W15*X15)+(U15*V15) -> 208 | Z15: =((P15*$AF$7)+(Y15*$AF$8/100)*$AG$7)+Events!$H15+Events!$I15+Events!$J15+Events!$R15+Events!$Q15+Tabla1[[#This Row],[COMPLEMENT RESPONSABLE EVENT]] -> 264.19184 | AA15: 3368 | AB15: =AA15/SUM($AA$2:$AA$38) -> 0.0076142161 | AD15: 45383 | AE15: 5683.95 | AF15: 7818.3 | AG15: 4803.75
A16: 45314 | B16: 45292 | C16: EVENTS | D16: EXTERN | E16: COCTEL | F16: SOLSONA | G16: E- Solsona Comunicació x 200MM | H16: =(VLOOKUP(B16,$AD$12:$AG$17,2,0)*AB16) -> 236.85981 | I16: =(VLOOKUP(B16,$AD$12:$AG$17,3,0)*AB16) -> 262.16861 | J16: =(VLOOKUP(B16,$AD$12:$AG$17,4,0)*AB16) -> 189.00376 | K16: 0 | L16: 2 | M16: 12.75 | N16: 0 | O16: 0 | P16: =(L16*M16)+(N16*O16) -> 25.5 | Q16: 0 | R16: 35.83 | S16: 0 | T16: 116 | U16: 1 | V16: 116 | W16: 2 | X16: 116 | Y16: =(S16*T16)+(W16*X16)+(U16*V16) -> 348 | Z16: =((P16*$AF$7)+(Y16*$AF$8/100)*$AG$7)+Events!$H16+Events!$I16+Events!$J16+Events!$R16+Events!$Q16+Tabla1[[#This Row],[COMPLEMENT RESPONSABLE EVENT]] -> 1274.943 | AA16: 19420 | AB16: =AA16/SUM($AA$2:$AA$38) -> 0.043903823 | AD16: 45413 | AE16: 6577.12 | AF16: 8510 | AG16: 5978.4
A17: 45315 | B17: 45292 | C17: EVENTS | D17: EXTERN | E17: BANQUET | F17: CODORNIU | G17: E Graphic PKG 150 MG | H17: =(VLOOKUP(B17,$AD$12:$AG$17,2,0)*AB17) -> 170.24146 | I17: =(VLOOKUP(B17,$AD$12:$AG$17,3,0)*AB17) -> 188.432 | J17: =(VLOOKUP(B17,$AD$12:$AG$17,4,0)*AB17) -> 135.84524 | K17: 0 | L17: 2 | M17: 8.75 | N17: 2 | O17: 4 | P17: =(L17*M17)+(N17*O17) -> 25.5 | Q17: 0 | R17: 35.83 | S17: 0 | T17: 20 | U17: 1 | V17: 20 | W17: 1 | X17: 20 | Y17: =(S17*T17)+(W17*X17)+(U17*V17) -> 40 | Z17: =((P17*$AF$7)+(Y17*$AF$8/100)*$AG$7)+Events!$H17+Events!$I17+Events!$J17+Events!$R17+Events!$Q17+Tabla1[[#This Row],[COMPLEMENT RESPONSABLE EVENT]] -> 999.9327 | AA17: 13958 | AB17: =AA17/SUM($AA$2:$AA$38) -> 0.03155559 | AD17: 45444 | AE17: 8164.94 | AF17: 9360.88 | AG17: 6665.43
A18: 45315 | B18: 45292 | C18: EVENTS | D18: MASIA PROPIES | E18: BANQUET | F18: MASIA ESPLUGUES | G18: E IaG7 Mice 90 pax MG | H18: =(VLOOKUP(B18,$AD$12:$AG$17,2,0)*AB18) -> 108.27006 | I18: =(VLOOKUP(B18,$AD$12:$AG$17,3,0)*AB18) -> 119.83886 | J18: =(VLOOKUP(B18,$AD$12:$AG$17,4,0)*AB18) -> 86.394769 | K18: 0 | L18: 0 | M18: 0 | N18: 1 | O18: 3 | P18: =(L18*M18)+(N18*O18) -> 3 | Q18: 0 | R18: 35.83 | S18: 0 | T18: 104 | U18: 1 | V18: 104 | W18: 1 | X18: 104 | Y18: =(S18*T18)+(W18*X18)+(U18*V18) -> 208 | Z18: =((P18*$AF$7)+(Y18*$AF$8/100)*$AG$7)+Events!$H18+Events!$I18+Events!$J18+Events!$R18+Events!$Q18+Tabla1[[#This Row],[COMPLEMENT RESPONSABLE EVENT]] -> 459.37049 | AA18: 8877 | AB18: =AA18/SUM($AA$2:$AA$38) -> 0.020068704 | AD18: 45901 | AE18: =6709.19+2526.2 -> 9235.39 | AF18: =12949.74+2704.16 -> 15653.9 | AG18: =7399.83+2557.95 -> 9957.78
A19: 45315 | B19: 45292 | C19: EVENTS | D19: MASIA PROPIES | E19: BUFFET | F19: CLOS LA PLANA | G19: E-PANGEA DINNER 120 PAX afv / E-ONE EVENT GALA DINNER 165 PAX AFV | H19: =(VLOOKUP(B19,$AD$12:$AG$17,2,0)*AB19) -> 271.41304 | I19: =(VLOOKUP(B19,$AD$12:$AG$17,3,0)*AB19) -> 300.4139 | J19: =(VLOOKUP(B19,$AD$12:$AG$17,4,0)*AB19) -> 216.57573 | K19: 0 | L19: 3 | M19: 10.3 | N19: 0 | O19: 0 | P19: =(L19*M19)+(N19*O19) -> 30.9 | Q19: 0 | R19: 35.83 | S19: 0 | T19: 80 | U19: 1 | V19: 80 | W19: 2 | X19: 80 | Y19: =(S19*T19)+(W19*X19)+(U19*V19) -> 240 | Z19: =((P19*$AF$7)+(Y19*$AF$8/100)*$AG$7)+Events!$H19+Events!$I19+Events!$J19+Events!$R19+Events!$Q19+Tabla1[[#This Row],[COMPLEMENT RESPONSABLE EVENT]] -> 1443.9367 | AA19: 22253 | AB19: =AA19/SUM($AA$2:$AA$38) -> 0.050308536
A20: 45316 | B20: 45292 | C20: EVENTS | D20: EXTERN | E20: COFFEE | F20: FABRICA DAMM | G20: E - CreativeSpirits coffee MWC 100 cristina | H20: =(VLOOKUP(B20,$AD$12:$AG$17,2,0)*AB20) -> 36.49251 | I20: =(VLOOKUP(B20,$AD$12:$AG$17,3,0)*AB20) -> 40.391785 | J20: =(VLOOKUP(B20,$AD$12:$AG$17,4,0)*AB20) -> 29.119426 | K20: 0 | L20: 1 | M20: 9.95 | N20: 0 | O20: 0 | P20: =(L20*M20)+(N20*O20) -> 9.95 | Q20: 0 | R20: 35.83 | S20: 0 | T20: 120 | U20: 1 | V20: 120 | W20: 1 | X20: 120 | Y20: =(S20*T20)+(W20*X20)+(U20*V20) -> 240 | Z20: =((P20*$AF$7)+(Y20*$AF$8/100)*$AG$7)+Events!$H20+Events!$I20+Events!$J20+Events!$R20+Events!$Q20+Tabla1[[#This Row],[COMPLEMENT RESPONSABLE EVENT]] -> 384.43772 | AA20: 2992 | AB20: =AA20/SUM($AA$2:$AA$38) -> 0.0067641729
A21: 45316 | B21: 45292 | C21: EVENTS | D21: EXTERN | E21: BUFFET | F21: SIMON | G21: E - Solsona com X 200 dinar MM | H21: =(VLOOKUP(B21,$AD$12:$AG$17,2,0)*AB21) -> 162.21604 | I21: =(VLOOKUP(B21,$AD$12:$AG$17,3,0)*AB21) -> 179.54905 | J21: =(VLOOKUP(B21,$AD$12:$AG$17,4,0)*AB21) -> 129.4413 | K21: 0 | L21: 2 | M21: 11.1 | N21: 2 | O21: 5.25 | P21: =(L21*M21)+(N21*O21) -> 32.7 | Q21: 0 | R21: 35.83 | S21: 1 | T21: 118 | U21: 1 | V21: 118 | W21: 1 | X21: 118 | Y21: =(S21*T21)+(W21*X21)+(U21*V21) -> 354 | Z21: =((P21*$AF$7)+(Y21*$AF$8/100)*$AG$7)+Events!$H21+Events!$I21+Events!$J21+Events!$R21+Events!$Q21+Tabla1[[#This Row],[COMPLEMENT RESPONSABLE EVENT]] -> 1189.3048 | AA21: 13300 | AB21: =AA21/SUM($AA$2:$AA$38) -> 0.030068015
A22: 45317 | B22: 45292 | C22: EVENTS | D22: EXTERN | E22: COCTEL | F22: LA PEDRERA | G22: E -euromotivation 30 gala-laia | H22: =(VLOOKUP(B22,$AD$12:$AG$17,2,0)*AB22) -> 47.054848 | I22: =(VLOOKUP(B22,$AD$12:$AG$17,3,0)*AB22) -> 52.082723 | J22: =(VLOOKUP(B22,$AD$12:$AG$17,4,0)*AB22) -> 37.547709 | K22: 0 | L22: 1 | M22: 13.35 | N22: 0 | O22: 0 | P22: =(L22*M22)+(N22*O22) -> 13.35 | Q22: 0 | R22: 35.83 | S22: 0 | T22: 112 | U22: 1 | V22: 112 | W22: 1 | X22: 112 | Y22: =(S22*T22)+(W22*X22)+(U22*V22) -> 224 | Z22: =((P22*$AF$7)+(Y22*$AF$8/100)*$AG$7)+Events!$H22+Events!$I22+Events!$J22+Events!$R22+Events!$Q22+Tabla1[[#This Row],[COMPLEMENT RESPONSABLE EVENT]] -> 472.08568 | AA22: 3858 | AB22: =AA22/SUM($AA$2:$AA$38) -> 0.008721985
A23: 45317 | B23: 45292 | C23: EVENTS | D23: MASIA PROPIES | E23: PAELLES | F23: MASIA ESPLUGUES | G23: E - One event ccurs 140 MG | H23: =(VLOOKUP(B23,$AD$12:$AG$17,2,0)*AB23) -> 143.77464 | I23: =(VLOOKUP(B23,$AD$12:$AG$17,3,0)*AB23) -> 159.13715 | J23: =(VLOOKUP(B23,$AD$12:$AG$17,4,0)*AB23) -> 114.72587 | K23: 0 | L23: 0 | M23: 0 | N23: 1 | O23: 3 | P23: =(L23*M23)+(N23*O23) -> 3 | Q23: 0 | R23: 35.83 | S23: 0 | T23: 104 | U23: 1 | V23: 104 | W23: 1 | X23: 104 | Y23: =(S23*T23)+(W23*X23)+(U23*V23) -> 208 | Z23: =((P23*$AF$7)+(Y23*$AF$8/100)*$AG$7)+Events!$H23+Events!$I23+Events!$J23+Events!$R23+Events!$Q23+Tabla1[[#This Row],[COMPLEMENT RESPONSABLE EVENT]] -> 562.50446 | AA23: 11788 | AB23: =AA23/SUM($AA$2:$AA$38) -> 0.026649756
A24: 45317 | B24: 45292 | C24: EVENTS | D24: EXTERN | E24: CALÇOTADA | F24: MIRADOR | G24: E- EL TELER calçotada x 150 MM | H24: =(VLOOKUP(B24,$AD$12:$AG$17,2,0)*AB24) -> 44.408165 | I24: =(VLOOKUP(B24,$AD$12:$AG$17,3,0)*AB24) -> 49.153239 | J24: =(VLOOKUP(B24,$AD$12:$AG$17,4,0)*AB24) -> 35.435772 | K24: 0 | L24: 0 | M24: 0 | N24: 1 | O24: 2 | P24: =(L24*M24)+(N24*O24) -> 2 | Q24: 0 | R24: 35.83 | S24: 0 | T24: 26 | U24: 1 | V24: 26 | W24: 1 | X24: 26 | Y24: =(S24*T24)+(W24*X24)+(U24*V24) -> 52 | Z24: =((P24*$AF$7)+(Y24*$AF$8/100)*$AG$7)+Events!$H24+Events!$I24+Events!$J24+Events!$R24+Events!$Q24+Tabla1[[#This Row],[COMPLEMENT RESPONSABLE EVENT]] -> 214.58638 | AA24: 3641 | AB24: =AA24/SUM($AA$2:$AA$38) -> 0.0082314016
A25: 45317 | B25: 45292 | C25: EVENTS | D25: EXTERN | E25: COCTEL | F25: LA PEDRERA | G25: E-VAUS ESTUDIO COCTEL LUNCH 190PAX AFV | H25: =(VLOOKUP(B25,$AD$12:$AG$17,2,0)*AB25) -> 190.26844 | I25: =(VLOOKUP(B25,$AD$12:$AG$17,3,0)*AB25) -> 210.59888 | J25: =(VLOOKUP(B25,$AD$12:$AG$17,4,0)*AB25) -> 151.82589 | K25: 0 | L25: 2 | M25: 13.4 | N25: 0 | O25: 0 | P25: =(L25*M25)+(N25*O25) -> 26.8 | Q25: 0 | R25: 35.83 | S25: 0 | T25: 112 | U25: 1 | V25: 112 | W25: 2 | X25: 112 | Y25: =(S25*T25)+(W25*X25)+(U25*V25) -> 336 | Z25: =((P25*$AF$7)+(Y25*$AF$8/100)*$AG$7)+Events!$H25+Events!$I25+Events!$J25+Events!$R25+Events!$Q25+Tabla1[[#This Row],[COMPLEMENT RESPONSABLE EVENT]] -> 1159.8288 | AA25: 15600 | AB25: =AA25/SUM($AA$2:$AA$38) -> 0.035267747
A26: 45318 | B26: 45292 | C26: EVENTS | D26: EXTERN | E26: COCTEL | F26: LA PEDRERA | G26: E-FRIMM coffee o cctel 100-laia | H26: =(VLOOKUP(B26,$AD$12:$AG$17,2,0)*AB26) -> 82.266705 | I26: =(VLOOKUP(B26,$AD$12:$AG$17,3,0)*AB26) -> 91.057016 | J26: =(VLOOKUP(B26,$AD$12:$AG$17,4,0)*AB26) -> 65.645231 | K26: 0 | L26: 1 | M26: 10.85 | N26: 0 | O26: 0 | P26: =(L26*M26)+(N26*O26) -> 10.85 | Q26: 0 | R26: 35.83 | S26: 0 | T26: 112 | U26: 1 | V26: 112 | W26: 1 | X26: 112 | Y26: =(S26*T26)+(W26*X26)+(U26*V26) -> 224 | Z26: =((P26*$AF$7)+(Y26*$AF$8/100)*$AG$7)+Events!$H26+Events!$I26+Events!$J26+Events!$R26+Events!$Q26+Tabla1[[#This Row],[COMPLEMENT RESPONSABLE EVENT]] -> 529.36935 | AA26: 6745 | AB26: =AA26/SUM($AA$2:$AA$38) -> 0.015248779
A27: 45318 | B27: 45292 | C27: EVENTS | D27: MASIA PROPIES | E27: COCTEL | F27: MASIA ESPLUGUES | G27: E Aggtelek cctel 250 MG | H27: =(VLOOKUP(B27,$AD$12:$AG$17,2,0)*AB27) -> 220.69919 | I27: =(VLOOKUP(B27,$AD$12:$AG$17,3,0)*AB27) -> 244.2812 | J27: =(VLOOKUP(B27,$AD$12:$AG$17,4,0)*AB27) -> 176.1083 | K27: 0 | L27: 0 | M27: 0 | N27: 1 | O27: 3 | P27: =(L27*M27)+(N27*O27) -> 3 | Q27: 0 | R27: 35.83 | S27: 0 | T27: 104 | U27: 1 | V27: 104 | W27: 1 | X27: 104 | Y27: =(S27*T27)+(W27*X27)+(U27*V27) -> 208 | Z27: =((P27*$AF$7)+(Y27*$AF$8/100)*$AG$7)+Events!$H27+Events!$I27+Events!$J27+Events!$R27+Events!$Q27+Tabla1[[#This Row],[COMPLEMENT RESPONSABLE EVENT]] -> 785.95548 | AA27: 18095 | AB27: =AA27/SUM($AA$2:$AA$38) -> 0.040908325
A28: 45318 | B28: 45292 | C28: EVENTS | D28: EXTERN | E28: BRUNCH | F28: CASA CORBERA | G28: P - NATALIE x 50 afv | H28: =(VLOOKUP(B28,$AD$12:$AG$17,2,0)*AB28) -> 25.856992 | I28: =(VLOOKUP(B28,$AD$12:$AG$17,3,0)*AB28) -> 28.619848 | J28: =(VLOOKUP(B28,$AD$12:$AG$17,4,0)*AB28) -> 20.632749 | K28: 0 | L28: 1 | M28: 10.75 | N28: 0 | O28: 0 | P28: =(L28*M28)+(N28*O28) -> 10.75 | Q28: 0 | R28: 35.83 | S28: 0 | T28: 88 | U28: 1 | V28: 88 | W28: 1 | X28: 88 | Y28: =(S28*T28)+(W28*X28)+(U28*V28) -> 176 | Z28: =((P28*$AF$7)+(Y28*$AF$8/100)*$AG$7)+Events!$H28+Events!$I28+Events!$J28+Events!$R28+Events!$Q28+Tabla1[[#This Row],[COMPLEMENT RESPONSABLE EVENT]] -> 351.00919 | AA28: 2120 | AB28: =AA28/SUM($AA$2:$AA$38) -> 0.0047927963
A29: 45320 | B29: 45292 | C29: EVENTS | D29: EXTERN | E29: BUFFET | F29: CASA DEL MAR | G29: E- CSM LOTUS 250 AFV | H29: =(VLOOKUP(B29,$AD$12:$AG$17,2,0)*AB29) -> 344.87374 | I29: =(VLOOKUP(B29,$AD$12:$AG$17,3,0)*AB29) -> 381.72397 | J29: =(VLOOKUP(B29,$AD$12:$AG$17,4,0)*AB29) -> 275.19415 | K29: 0 | L29: 4 | M29: 17 | N29: 0 | O29: 0 | P29: =(L29*M29)+(N29*O29) -> 68 | Q29: 0 | R29: 35.83 | S29: 0 | T29: 84 | U29: 1 | V29: 84 | W29: 4 | X29: 84 | Y29: =(S29*T29)+(W29*X29)+(U29*V29) -> 420 | Z29: =((P29*$AF$7)+(Y29*$AF$8/100)*$AG$7)+Events!$H29+Events!$I29+Events!$J29+Events!$R29+Events!$Q29+Tabla1[[#This Row],[COMPLEMENT RESPONSABLE EVENT]] -> 2372.7539 | AA29: 28276 | AB29: =AA29/SUM($AA$2:$AA$38) -> 0.063925052
A30: 45320 | B30: 45292 | C30: EVENTS | D30: EXTERN | E30: COCTEL | F30: GO BEACH | G30: E-MICE AND TRAIN PAX A CONF AFV | H30: =(VLOOKUP(B30,$AD$12:$AG$17,2,0)*AB30) -> 0 | I30: =(VLOOKUP(B30,$AD$12:$AG$17,3,0)*AB30) -> 0 | J30: =(VLOOKUP(B30,$AD$12:$AG$17,4,0)*AB30) -> 0 | K30: 0 | L30: 1 | M30: 8.3 | N30: 0 | O30: 0 | P30: =(L30*M30)+(N30*O30) -> 8.3 | Q30: 0 | R30: 35.83 | S30: 0 | T30: 0 | U30: 1 | V30: 130 | W30: 1 | X30: 130 | Y30: =(S30*T30)+(W30*X30)+(U30*V30) -> 260 | Z30: =((P30*$AF$7)+(Y30*$AF$8/100)*$AG$7)+Events!$H30+Events!$I30+Events!$J30+Events!$R30+Events!$Q30+Tabla1[[#This Row],[COMPLEMENT RESPONSABLE EVENT]] -> 254.026 | AA30: 0 | AB30: =AA30/SUM($AA$2:$AA$38) -> 0
... A38: 45322 | B38: 45292 | C38: EVENTS | D38: MASIA PROPIES | E38: COFFEE | F38: CAN PARELLADA | G38: E-VOLVO CARS 40 pax afv | H38: =(VLOOKUP(B38,$AD$12:$AG$17,2,0)*AB38) -> 224.56554 | I38: =(VLOOKUP(B38,$AD$12:$AG$17,3,0)*AB38) -> 248.56068 | J38: =(VLOOKUP(B38,$AD$12:$AG$17,4,0)*AB38) -> 179.19348 | K38: 0 | L38: 0 | M38: 0 | N38: 6 | O38: 3 | P38: =(L38*M38)+(N38*O38) -> 18 | Q38: 0 | R38: 35.83 | S38: 0 | T38: 42 | U38: 0 | V38: 42 | W38: 6 | X38: 42 | Y38: =(S38*T38)+(W38*X38)+(U38*V38) -> 252 | Z38: =((P38*$AF$7)+(Y38*$AF$8/100)*$AG$7)+Events!$H38+Events!$I38+Events!$J38+Events!$R38+Events!$Q38+Tabla1[[#This Row],[COMPLEMENT RESPONSABLE EVENT]] -> 1078.8289 | AA38: 18412 | AB38: =AA38/SUM($AA$2:$AA$38) -> 0.041624984
A39: 45322 | B39: 45292 | C39: FOOD LOVERS | F39: FOOD LOVERS | H39: 0 | I39: 0 | J39: 0 | K39: 0 | L39: 0 | M39: 0 | N39: 0 | O39: 0 | P39: =(L39*M39)+(N39*O39) -> 0 | Q39: 0 | R39: 0 | S39: 0 | T39: 0 | U39: 0 | V39: 0 | W39: 0 | X39: 0 | Y39: =(S39*T39)+(W39*X39)+(U39*V39) -> 0 | Z39: =((P39*$AF$7)+(Y39*$AF$8/100)*$AG$7)+Events!$H39+Events!$I39+Events!$J39+Events!$R39+Events!$Q39 -> 0 | AB39: =IF(ISERROR(Z39/AA39),"",(Z39/AA39))
A40: 45293 | B40: 45292 | C40: ATMETLLER | F40: ATMETLLER | H40: 0 | I40: 0 | J40: 0 | K40: 0 | L40: 2 | M40: 4 | N40: 0 | O40: 0 | P40: =(L40*M40)+(N40*O40) -> 8 | Q40: 0 | R40: 9.22 | S40: 0 | T40: 0 | U40: 0 | V40: 0 | W40: 2 | X40: 208 | Y40: =(S40*T40)+(W40*X40)+(U40*V40) -> 416 | Z40: =((P40*$AF$7)+(Y40*$AF$8/100)*$AG$7)+Events!$H40+Events!$I40+Events!$J40+Events!$R40+Events!$Q40+Tabla1[[#This Row],[COMPLEMENT RESPONSABLE EVENT]] -> 263.2936 | AB40: =IF(ISERROR(Z40/AA40),"",(Z40/AA40))
A41: 45294 | B41: 45292 | C41: ATMETLLER | F41: ATMETLLER | H41: 0 | I41: 0 | J41: 0 | K41: 0 | L41: 1 | M41: 4 | N41: 0 | O41: 0 | P41: =(L41*M41)+(N41*O41) -> 4 | Q41: 0 | R41: 9.22 | S41: 0 | T41: 0 | U41: 0 | V41: 0 | W41: 1 | X41: 104 | Y41: =(S41*T41)+(W41*X41)+(U41*V41) -> 104 | Z41: =((P41*$AF$7)+(Y41*$AF$8/100)*$AG$7)+Events!$H41+Events!$I41+Events!$J41+Events!$R41+Events!$Q41+Tabla1[[#This Row],[COMPLEMENT RESPONSABLE EVENT]] -> 108.7384 | AB41: =IF(ISERROR(Z41/AA41),"",(Z41/AA41))
A42: 45295 | B42: 45292 | C42: ATMETLLER | F42: ATMETLLER | H42: 0 | I42: 0 | J42: 0 | K42: 0 | L42: 1 | M42: 4 | N42: 0 | O42: 0 | P42: =(L42*M42)+(N42*O42) -> 4 | Q42: 0 | R42: 9.22 | S42: 0 | T42: 0 | U42: 0 | V42: 0 | W42: 1 | X42: 104 | Y42: =(S42*T42)+(W42*X42)+(U42*V42) -> 104 | Z42: =((P42*$AF$7)+(Y42*$AF$8/100)*$AG$7)+Events!$H42+Events!$I42+Events!$J42+Events!$R42+Events!$Q42+Tabla1[[#This Row],[COMPLEMENT RESPONSABLE EVENT]] -> 108.7384 | AB42: =IF(ISERROR(Z42/AA42),"",(Z42/AA42))
A43: 45296 | B43: 45292 | C43: ATMETLLER | F43: ATMETLLER | H43: 0 | I43: 0 | J43: 0 | K43: 0 | L43: 1 | M43: 4 | N43: 0 | O43: 0 | P43: =(L43*M43)+(N43*O43) -> 4 | Q43: 0 | R43: 9.22 | S43: 0 | T43: 0 | U43: 0 | V43: 0 | W43: 1 | X43: 104 | Y43: =(S43*T43)+(W43*X43)+(U43*V43) -> 104 | Z43: =((P43*$AF$7)+(Y43*$AF$8/100)*$AG$7)+Events!$H43+Events!$I43+Events!$J43+Events!$R43+Events!$Q43+Tabla1[[#This Row],[COMPLEMENT RESPONSABLE EVENT]] -> 108.7384 | AB43: =IF(ISERROR(Z43/AA43),"",(Z43/AA43))
A44: 45299 | B44: 45292 | C44: ATMETLLER | F44: ATMETLLER | H44: 0 | I44: 0 | J44: 0 | K44: 0 | L44: 1 | M44: 4 | N44: 0 | O44: 0 | P44: =(L44*M44)+(N44*O44) -> 4 | Q44: 0 | R44: 9.22 | S44: 0 | T44: 0 | U44: 0 | V44: 0 | W44: 1 | X44: 104 | Y44: =(S44*T44)+(W44*X44)+(U44*V44) -> 104 | Z44: =((P44*$AF$7)+(Y44*$AF$8/100)*$AG$7)+Events!$H44+Events!$I44+Events!$J44+Events!$R44+Events!$Q44+Tabla1[[#This Row],[COMPLEMENT RESPONSABLE EVENT]] -> 108.7384 | AB44: =IF(ISERROR(Z44/AA44),"",(Z44/AA44))
A45: 45300 | B45: 45292 | C45: ATMETLLER | F45: ATMETLLER | H45: 0 | I45: 0 | J45: 0 | K45: 0 | L45: 1 | M45: 4 | N45: 0 | O45: 0 | P45: =(L45*M45)+(N45*O45) -> 4 | Q45: 0 | R45: 9.22 | S45: 0 | T45: 0 | U45: 0 | V45: 0 | W45: 1 | X45: 104 | Y45: =(S45*T45)+(W45*X45)+(U45*V45) -> 104 | Z45: =((P45*$AF$7)+(Y45*$AF$8/100)*$AG$7)+Events!$H45+Events!$I45+Events!$J45+Events!$R45+Events!$Q45+Tabla1[[#This Row],[COMPLEMENT RESPONSABLE EVENT]] -> 108.7384 | AB45: =IF(ISERROR(Z45/AA45),"",(Z45/AA45))
A46: 45301 | B46: 45292 | C46: ATMETLLER | F46: ATMETLLER | H46: 0 | I46: 0 | J46: 0 | K46: 0 | L46: 1 | M46: 4 | N46: 0 | O46: 0 | P46: =(L46*M46)+(N46*O46) -> 4 | Q46: 0 | R46: 9.22 | S46: 0 | T46: 0 | U46: 0 | V46: 0 | W46: 1 | X46: 104 | Y46: =(S46*T46)+(W46*X46)+(U46*V46) -> 104 | Z46: =((P46*$AF$7)+(Y46*$AF$8/100)*$AG$7)+Events!$H46+Events!$I46+Events!$J46+Events!$R46+Events!$Q46+Tabla1[[#This Row],[COMPLEMENT RESPONSABLE EVENT]] -> 108.7384 | AB46: =IF(ISERROR(Z46/AA46),"",(Z46/AA46))
A47: 45302 | B47: 45292 | C47: ATMETLLER | F47: ATMETLLER | H47: 0 | I47: 0 | J47: 0 | K47: 0 | L47: 1 | M47: 4 | N47: 0 | O47: 0 | P47: =(L47*M47)+(N47*O47) -> 4 | Q47: 0 | R47: 9.22 | S47: 0 | T47: 0 | U47: 0 | V47: 0 | W47: 1 | X47: 104 | Y47: =(S47*T47)+(W47*X47)+(U47*V47) -> 104 | Z47: =((P47*$AF$7)+(Y47*$AF$8/100)*$AG$7)+Events!$H47+Events!$I47+Events!$J47+Events!$R47+Events!$Q47+Tabla1[[#This Row],[COMPLEMENT RESPONSABLE EVENT]] -> 108.7384 | AB47: =IF(ISERROR(Z47/AA47),"",(Z47/AA47))
...

Sheet % DEPT. LOG.
A1: GRUP | B1: CASAMENTS
A3: Etiquetas de fila | B3: TOTAL COST | C3: PREPARACIÓ | D3: % PREPARACIÓ&TOTAL COST | E3: GESTIÓ LOGÍSTICA | F3: % GESTIÓ & TOTAL COST | G3: PERSONAL DE RENTAT | H3: % RENTAT & TOTAL COST | I3: TOTAL HORES | J3: IMPORT HORES EVENT | K3: % IMPORT EVENTS & TOTAL COST
A4: 45292 | B4: 1875.9434 | C4: 166.61611 | D4: 0.088817242 | E4: 150.5316 | F4: 0.08024315 | G4: 120.11763 | H4: 0.064030523 | I4: 70.88 | J4: 1275.84 | K4: 0.68010582
A5: 45352 | B5: 2128.5177 | C5: 594.07248 | D5: 0.2791015 | E5: 608.73191 | F5: 0.28598865 | G5: 444.2573 | H5: 0.20871675 | I5: 18.3 | J5: 329.4 | K5: 0.15475559
A6: 45383 | B6: 8445.4047 | C6: 1932.8296 | D6: 0.22886169 | E6: 1405.1785 | F6: 0.16638379 | G6: 1187.5766 | H6: 0.14061808 | I6: 192.75 | J6: 3469.5 | K6: 0.41081513
A7: 45413 | B7: 23958.421 | C7: 3245.937 | D7: 0.13548209 | E7: 2508.6859 | F7: 0.10470998 | G7: 2280.3184 | H7: 0.095178158 | I7: 763.24 | J7: 13738.32 | K7: 0.57342343
A8: 45444 | B8: 36004.987 | C8: 3476.5395 | D8: 0.096557166 | E8: 3032.3791 | F8: 0.084221084 | G8: 2475.4757 | H8: 0.068753689 | I8: 1300.14 | J8: 23402.52 | K8: 0.64997995
A9: Total general | B9: 72413.274 | C9: 9415.9947 | D9: 0.13003133 | E9: 7705.507 | F9: 0.10641014 | G9: 6507.7456 | H9: 0.089869512 | I9: 2345.31 | J9: 42215.58 | K9: 0.58298123

Sheet Cost Events_Casaments 
A1: ESPAI | B1: (Todas)
A2: GRUP | B2: (Todas)
A4: Etiquetas de fila | B4: TOTAL COST | C4: FACTURACIO | D4: % LOG&FACT | I4: Cost Perparacio | J4: Etiquetas de fila | K4: TOTAL COST | L4: FACTURACIO | M4: Suma de % COST | N4: falta numero de pax
A5: 19TH HOLE | B5: 3030.9884 | C5: 30166 | D5: 0.10047697 | I5: 1 | J5: BLAYET | K5: 2203.2571 | L5: 18795 | M5: 0.11722571
A6: ACLAM | B6: 544.39005 | C6: 3476 | D6: 0.15661394 | I6: 1 | J6: BUFFET | K6: 7872.5946 | L6: 96003 | M6: 0.082003631
A7: AGO GRANOLLERS | B7: 1485.9844 | C7: 15734 | D7: 0.09444416 | I7: 0.4 | J7: CASAMENT | K7: 72413.274 | L7: 1165133.7 | M7: 0.062150184
A8: ALIMENTARIA | B8: 337.24985 | C8: 4445 | D8: 0.075871731 | I8: 1 | J8: COCTEL | K8: 95159.521 | L8: 1230627 | M8: 0.077326047
A9: AQUARIUM | B9: 884.81429 | C9: 7400 | D9: 0.1195695 | I9: 1 | J9: COFFEE | K9: 10135.106 | L9: 131720.2 | M9: 0.076944201
A10: ARBOÇ | B10: 1202.29 | C10: 11900 | D10: 0.10103277 | I10: 0.1 | J10: COPA DE CAVA | K10: 2205.416 | L10: 23153 | M10: 0.095254006
A11: ASTORIA | B11: 866.65779 | C11: 9900 | D11: 0.087541191 | I11: 0.4 | J11: FAMILY DAY | K11: 3655.64 | L11: 35900 | M11: 0.10182841
A12: AT ROCA | B12: 339.96987 | C12: 2465 | D12: 0.13791881 | I12: 1 | J12: FIRA | K12: 11073.128 | L12: 424000 | M12: 0.026115869
A13: ATMETLLER | B13: 17712.691 | D13: #DIV/0! | I13: 1 | J13: FOOD LOVERS | K13: 2916.1007 | L13: 9450 | M13: 0.30858208
A14: AXA | B14: 6968.1199 | C14: 87188.2 | D14: 0.079920447 | I14: 1 | J14: PAELLES | K14: 5731.4646 | L14: 77247 | M14: 0.074196598
A15: BROOKLING | B15: 487.25301 | C15: 6272 | D15: 0.077687023 | I15: 1 | J15: PARADETES | K15: 5501.0318 | L15: 69357 | M15: 0.079314731
A16: CAIXABANK | B16: 447.50852 | C16: 3060 | D16: 0.14624461 | I16: 1 | J16: BANQUET | K16: 69889.242 | L16: 781961.3 | M16: 0.089376855
A17: CAMBRA BCN | B17: 213.76419 | C17: 1495 | D17: 0.14298608 | I17: 1 | J17: CALÇOTADA | K17: 1687.429 | L17: 18476 | M17: 0.091330861
A18: CAN BOSCH | B18: 173.48902 | C18: 2720 | D18: 0.063782728 | I18: 1 | J18: BARBACOA | K18: 2556.6307 | L18: 27074 | M18: 0.094431213
A19: CAN PARELLADA | B19: 6082.3012 | C19: 97013.79 | D19: 0.062695223 | J19: Total general | K19: 292999.84 | L19: 4108897.2 | M19: 0.071308631
A20: CASA BATLLÓ | B20: 2237.2203 | C20: 22237 | D20: 0.10060801
A21: CASA CORBERA | B21: 704.71838 | C21: 4240 | D21: 0.16620716
A22: CASA DE LES PUNXES | B22: 1195.3394 | C22: 9524 | D22: 0.12550812
A23: CASA DEL MAR | B23: 6075.571 | C23: 67559.5 | D23: 0.089929188 | I23: Preparador en funcio del tipus de servei
A24: CASTELL PENYAFORT | B24: 263.1711 | C24: 1300 | D24: 0.2024393 | I24: Rentador en funcionumero de pax i serveis
A25: CAVES LLOPART | B25: 454.63494 | C25: 5000 | D25: 0.090926987
A26: CIRCUIT CATALUNYA | B26: 1509.5035 | C26: 9063 | D26: 0.16655671
A27: CLINICA PLANES | B27: 616.79213 | C27: 7203 | D27: 0.085629895
A28: CLOS LA PLANA | B28: 26630.535 | C28: 413392.26 | D28: 0.06441953
A29: CODORNIU | B29: 10876.629 | C29: 128727 | D29: 0.084493767
A30: CONVENT DELS ANGELS | B30: 537.36294 | C30: 5000 | D30: 0.10747259
A31: CORNELLÀ | B31: 781.57128 | C31: 6000 | D31: 0.13026188
A32: DAMM | B32: 1245.0638 | C32: 10897 | D32: 0.11425748
A33: DFACTORY | B33: 836.50551 | C33: 9739.3 | D33: 0.085889695
A34: DOWNTOWN | B34: 1827.3576 | C34: 25604 | D34: 0.071370004
A35: DRASSANES | B35: 4424.909 | C35: 42651 | D35: 0.1037469
A36: ELS CASSOTS | B36: 223.92024 | C36: 1600 | D36: 0.13995015
... A45: FONT DE LA CANYA | B45: 17773.778 | C45: 318348.61 | D45: 0.055831179
A46: FOOD LOVERS | B46: 0 | D46: #DIV/0!
A47: FORUM GIRONA | B47: 109.72 | D47: #DIV/0!
A48: FUNDACIÓ TÀPIES | B48: 1613.6153 | C48: 13712 | D48: 0.11767907
A49: GESTAMP | B49: 1206.3865 | C49: 14000 | D49: 0.086170462
...

Sheet Resum 
A1: Suma de TOTAL COST | B1: Etiquetas de columna | H1: %
A2: Etiquetas de fila | B2: EVENTS | C2: RESTAURANTS | D2: FOOD LOVERS | E2: CASAMENTS | F2: ATMETLLER | G2: Total general | H2: EVENTS | I2: RESTAURANTS | J2: FOOD LOVERS | K2: CASAMENTS | L2: ATMETLLER
A3: 45292 | B3: 30716.833 | C3: 4008.78 | D3: 0 | E3: 1875.9434 | F3: 3243.4288 | G3: 39844.985 | H3: =GETPIVOTDATA("TOTAL COST ",$A$1,"MESOS",DATE(2024,1,1),"GRUP","EVENTS")/GETPIVOTDATA("TOTAL COST ",$A$1,"MESOS",DATE(2024,1,1)) -> 0.77090838 | I3: =C3/G3 -> 0.1006094 | J3: =D3/G3 -> 0 | K3: =E3/G3 -> 0.04708104 | L3: =F3/G3 -> 0.081401179
A4: 45323 | B4: 29889.471 | C4: 4249.1 | D4: 654.63 | F4: 2641.0284 | G4: 37434.229 | H4: =GETPIVOTDATA("TOTAL COST ",$A$1,"MESOS",DATE(2024,2,1),"GRUP","EVENTS")/GETPIVOTDATA("TOTAL COST ",$A$1,"MESOS",DATE(2024,2,1)) -> 0.79845295 | I4: =C4/G4 -> 0.11350841 | J4: =D4/G4 -> 0.017487471 | K4: =E4/G4 -> 0 | L4: =F4/G4 -> 0.070551162
A5: 45352 | B5: 32159.849 | C5: 4747.86 | D5: 109.72 | E5: 2128.5177 | F5: 2930.5152 | G5: 42076.462 | H5: =B5/G5 -> 0.76431923 | I5: =C5/G5 -> 0.11283886 | J5: =D5/G5 -> 0.0026076337 | K5: =E5/G5 -> 0.050586898 | L5: =F5/G5 -> 0.069647377
A6: 45383 | B6: 30162.409 | C6: 4400.3022 | D6: 59.66 | E6: 8445.4047 | F6: 2825.8952 | G6: 45893.671 | H6: =B6/G6 -> 0.65722372 | I6: =C6/G6 -> 0.09588037 | J6: =D6/G6 -> 0.0012999614 | K6: =E6/G6 -> 0.18402112 | L6: =F6/G6 -> 0.061574834
A7: 45413 | B7: 43881.18 | C7: 6070.68 | D7: 1084.34 | E7: 23958.421 | F7: 2786.5152 | G7: 77781.136 | H7: =B7/G7 -> 0.56416224 | I7: =C7/G7 -> 0.07804823 | J7: =D7/G7 -> 0.013940912 | K7: =E7/G7 -> 0.30802354 | L7: =F7/G7 -> 0.035825077
A8: 45444 | B8: 56994.448 | C8: 4112.53 | D8: 1007.7507 | E8: 36004.987 | F8: 3285.3084 | G8: 101405.02 | H8: =B8/G8 -> 0.56204758 | I8: =C8/G8 -> 0.040555485 | J8: =D8/G8 -> 0.0099378769 | K8: =E8/G8 -> 0.35506118 | L8: =F8/G8 -> 0.032397886
A9: Total general | B9: 223804.19 | C9: 27589.252 | D9: 2916.1007 | E9: 72413.274 | F9: 17712.691 | G9: 344435.51
